<?xml version="1.0" ?>
<!-- =================================================================================== -->
<!-- |    This document was autogenerated by xacro from /home/demi/godel_ws/src/yaskawa_gp25_support/urdf/gp25_workspace.xacro | -->
<!-- |    EDITING THIS FILE BY HAND IS NOT RECOMMENDED                                 | -->
<!-- =================================================================================== -->
<robot name="gp25_workspace" xmlns:xacro="http://ros.org/wiki/xacro">
    <!-- TBD -->
    <!--96"  vertical-->
    <!-- middle of width -->
    <link name="world_frame" />
    <!-- link list -->
    <link name="base_link">
        <visual>
            <origin rpy="0 0 0" xyz="0 0 0" />
            <geometry>
                <mesh filename="package://yaskawa_gp25_support/meshes/gp25/visual/base_axis.dae" />
            </geometry>
            <material name="blue">
                <color rgba="0 0 1 1" />
            </material>
        </visual>
        <collision>
            <geometry>
                <mesh filename="package://yaskawa_gp25_support/meshes/gp25/collision/base_axis.stl" />
            </geometry>
            <material name="yellow">
                <color rgba="0 1 1 1" />
            </material>
        </collision>
        
<inertial>
            <mass value="0.1" />
            <inertia ixx="0.03" iyy="0.03" izz="0.03" ixy="0.0" ixz="0.0" iyz="0.0" />
        </inertial>

    </link>
    <link name="link_1">
        <visual>
            <origin rpy="0 0 0" xyz="0 0 0" />
            <geometry>
                <mesh filename="package://yaskawa_gp25_support/meshes/gp25/visual/s_axis.dae" />
            </geometry>
            <material name="silver">
                <color rgba="0.8 0.8 0.8 1" />
            </material>
        </visual>
        <collision>
            <geometry>
                <mesh filename="package://yaskawa_gp25_support/meshes/gp25/collision/s_axis.stl" />
            </geometry>
            <material name="yellow" />
        </collision>
        
<inertial>
            <mass value="0.1" />
            <inertia ixx="0.03" iyy="0.03" izz="0.03" ixy="0.0" ixz="0.0" iyz="0.0" />
        </inertial>

    </link>
    <link name="link_2">
        <visual>
            <origin rpy="0 0 0" xyz="0 0 0" />
            <geometry>
                <mesh filename="package://yaskawa_gp25_support/meshes/gp25/visual/l_axis.dae" />
            </geometry>
            <material name="blue" />
        </visual>
        <collision>
            <geometry>
                <mesh filename="package://yaskawa_gp25_support/meshes/gp25/collision/l_axis.stl" />
            </geometry>
            <material name="yellow" />
        </collision>
        
<inertial>
            <mass value="0.1" />
            <inertia ixx="0.03" iyy="0.03" izz="0.03" ixy="0.0" ixz="0.0" iyz="0.0" />
        </inertial>

    </link>
    <link name="link_3">
        <visual>
            <origin rpy="0 0 0" xyz="0 0 0" />
            <geometry>
                <mesh filename="package://yaskawa_gp25_support/meshes/gp25/visual/u_axis.dae" />
            </geometry>
            <material name="silver" />
        </visual>
        <collision>
            <geometry>
                <mesh filename="package://yaskawa_gp25_support/meshes/gp25/collision/u_axis.stl" />
            </geometry>
            <material name="yellow" />
        </collision>
        
<inertial>
            <mass value="0.1" />
            <inertia ixx="0.03" iyy="0.03" izz="0.03" ixy="0.0" ixz="0.0" iyz="0.0" />
        </inertial>

    </link>
    <link name="link_4">
        <visual>
            <origin rpy="0 0 0" xyz="0 0 0" />
            <geometry>
                <mesh filename="package://yaskawa_gp25_support/meshes/gp25/visual/r_axis.dae" />
            </geometry>
            <material name="blue" />
        </visual>
        <collision>
            <geometry>
                <mesh filename="package://yaskawa_gp25_support/meshes/gp25/collision/r_axis.stl" />
            </geometry>
            <material name="yellow" />
        </collision>
        
<inertial>
            <mass value="0.1" />
            <inertia ixx="0.03" iyy="0.03" izz="0.03" ixy="0.0" ixz="0.0" iyz="0.0" />
        </inertial>

    </link>
    <link name="link_5">
        <visual>
            <origin rpy="0 0 0" xyz="0 0 0" />
            <geometry>
                <mesh filename="package://yaskawa_gp25_support/meshes/gp25/visual/b_axis.dae" />
            </geometry>
            <material name="silver" />
        </visual>
        <collision>
            <geometry>
                <mesh filename="package://yaskawa_gp25_support/meshes/gp25/collision/b_axis.stl" />
            </geometry>
            <material name="yellow" />
        </collision>
        
<inertial>
            <mass value="0.1" />
            <inertia ixx="0.03" iyy="0.03" izz="0.03" ixy="0.0" ixz="0.0" iyz="0.0" />
        </inertial>

    </link>
    <link name="link_6">
        <visual>
            <origin rpy="0 0 0" xyz="0 0 0" />
            <geometry>
                <mesh filename="package://yaskawa_gp25_support/meshes/gp25/visual/t_axis.dae" />
            </geometry>
            <material name="blue" />
        </visual>
        <collision>
            <geometry>
                <mesh filename="package://yaskawa_gp25_support/meshes/gp25/collision/t_axis.stl" />
            </geometry>
            <material name="yellow" />
        </collision>
        
<inertial>
            <mass value="0.1" />
            <inertia ixx="0.03" iyy="0.03" izz="0.03" ixy="0.0" ixz="0.0" iyz="0.0" />
        </inertial>

    </link>
    <link name="tool0" />
    <!-- end of link list -->
    <!-- joint list -->
    <joint name="joint_1" type="revolute">
        <parent link="base_link" />
        <child link="link_1" />
        <origin xyz="0 0 0" />
        <axis xyz="0 0 1" />
        <limit effort="100" lower="-3.14159265359" upper="3.14159265359" velocity="3.44" />
    </joint>
    <joint name="joint_2" type="revolute">
        <parent link="link_1" />
        <child link="link_2" />
        <origin xyz="0.150 0 0.505" />
        <axis xyz="0 1 0" />
        <limit effort="100" lower="-1.83259571459" upper="2.70526034059" velocity="3.32" />
    </joint>
    <joint name="joint_3" type="revolute">
        <parent link="link_2" />
        <child link="link_3" />
        <origin xyz="0 0 0.760" />
        <axis xyz="0 -1 0" />
        <!-- Limited wrt to datasheet to prevent self-collisions -->
        <limit effort="100" lower="-1.50098315672" upper="2.84488668075" velocity="3.67" />
    </joint>
    <joint name="joint_4" type="revolute">
        <parent link="link_3" />
        <child link="link_4" />
        <origin xyz="0 0 0.200" />
        <axis xyz="-1 0 0" />
        <limit effort="100" lower="-3.49065850399" upper="3.49065850399" velocity="7.16" />
    </joint>
    <joint name="joint_5" type="revolute">
        <parent link="link_4" />
        <child link="link_5" />
        <origin xyz="0.795 0 0" />
        <axis xyz="0 -1 0" />
        <limit effort="100" lower="-2.61799387799" upper="2.61799387799" velocity="7.16" />
    </joint>
    <joint name="joint_6" type="revolute">
        <parent link="link_5" />
        <child link="link_6" />
        <origin xyz="0.100 0 0" />
        <axis xyz="-1 0 0" />
        <limit effort="100" lower="-7.94124809657" upper="7.94124809657" velocity="10.82" />
    </joint>
    <joint name="joint_6-tool0" type="fixed">
        <parent link="link_6" />
        <child link="tool0" />
        <origin rpy="0 -1.57079632679 3.14159265359" xyz="0 0 0" />
    </joint>
    <!-- end of joint list -->
    <!-- ROS base_link to ABB World Coordinates transform -->
    <link name="base" />
    <joint name="base_link-base" type="fixed">
        <origin rpy="0 0 0" xyz="0 0 0" />
        <parent link="base_link" />
        <child link="base" />
    </joint>
    <!-- eff_frame is Base Link -->
    <link name="eff_frame" />
    <link name="adapter_tube">
        <visual>
            <geometry>
                <mesh filename="package://blending_end_effector/meshes/visual/Adapter_Tube.STL" />
            </geometry>
            <material name="grey">
                <color rgba="0.5 0.5 0.5 1.0" />
            </material>
        </visual>
        <collision>
            <geometry>
                <mesh filename="package://blending_end_effector/meshes/collision/adapter_tube_convex_hull.STL" />
            </geometry>
        </collision>
        
<inertial>
            <mass value="0.1" />
            <inertia ixx="0.03" iyy="0.03" izz="0.03" ixy="0.0" ixz="0.0" iyz="0.0" />
        </inertial>

    </link>
    <joint name="eff_frame_to_adapter_tube" type="fixed">
        <parent link="eff_frame" />
        <child link="adapter_tube" />
        <origin rpy="0 0 0" xyz="0 0 0" />
    </joint>
    <link name="bracket">
        <visual>
            <geometry>
                <mesh filename="package://blending_end_effector/meshes/visual/Tool_Mounting_Plate.STL" />
            </geometry>
            <material name="grey">
                <color rgba="0.5 0.5 0.5 1.0" />
            </material>
        </visual>
        <collision>
            <geometry>
                <mesh filename="package://blending_end_effector/meshes/collision/EE_and_Tool_Changer_convex_hull.STL" />
            </geometry>
        </collision>
        
<inertial>
            <mass value="0.1" />
            <inertia ixx="0.03" iyy="0.03" izz="0.03" ixy="0.0" ixz="0.0" iyz="0.0" />
        </inertial>

    </link>
    <joint name="adapter_tube_to_bracket" type="fixed">
        <parent link="adapter_tube" />
        <child link="bracket" />
        <origin rpy="0 0 0" xyz="0 0 0" />
    </joint>
    <link name="blending_tool">
        <visual>
            <geometry>
                <mesh filename="package://blending_end_effector/meshes/visual/Blending_Tool.STL" />
            </geometry>
            <material name="red">
                <color rgba="1 0 0 1" />
            </material>
        </visual>
    </link>
    <joint name="bracket_to_blending_tool" type="fixed">
        <parent link="bracket" />
        <child link="blending_tool" />
    </joint>
    <link name="ensenso">
        <visual>
            <geometry>
                <mesh filename="package://blending_end_effector/meshes/visual/Ensenso.STL" />
            </geometry>
            <material name="blue">
                <color rgba="0 0 1 1" />
            </material>
        </visual>
    </link>
    <joint name="bracket_to_ensenso" type="fixed">
        <parent link="bracket" />
        <child link="ensenso" />
    </joint>
    <link name="keyence">
        <visual>
            <geometry>
                <mesh filename="package://blending_end_effector/meshes/visual/Laser_Sensor.STL" />
            </geometry>
            <material name="yellow">
                <color rgba="1 1 0 1" />
            </material>
        </visual>
    </link>
    <joint name="bracket_to_keyence" type="fixed">
        <parent link="bracket" />
        <child link="keyence" />
    </joint>
    <!-- Frames for the motorized spindle on the end-->
    <link name="chuck_tip_frame" />
    <!--The tip of the chuck-->
    <link name="tcp_frame" />
    <!--The actual 'useful' work frame-->
    <joint name="bracket_to_chuck" type="fixed">
        <parent link="bracket" />
        <child link="chuck_tip_frame" />
        <origin rpy="0 -1.57079632679 0" xyz="-0.2507 -0.0035 0.1228" />
    </joint>
    <joint name="chuck_to_blend_tcp_frame" type="fixed">
        <parent link="chuck_tip_frame" />
        <child link="tcp_frame" />
        <origin rpy="0 0 0" xyz="0 0 0.04" />
    </joint>
    <!--Frames for the keyence profilometer-->
    <link name="keyence_sensor_optical_frame" />
    <!--The emitter lens-->
    <link name="keyence_tcp_frame" />
    <!--The nominal scan location (8cm forward of emitter)-->
    <joint name="bracket_to_keyence_sof" type="fixed">
        <parent link="bracket" />
        <child link="keyence_sensor_optical_frame" />
        <origin rpy="1.57079632679 1.57079632679 0 " xyz="0.0006 0.2863 0.0968" />
    </joint>
    <joint name="bracket_to_keyence_tcp_f" type="fixed">
        <parent link="bracket" />
        <child link="keyence_tcp_frame" />
        <origin rpy="-1.57079632679 1.57079632679 0" xyz="0.0006 0.2863 0.0968" />
    </joint>
    <!--Frames related to the motion of the camera-->
    <link name="ensenso_sensor_optical_frame" />
    <link name="kinect2_move_frame" />
    <joint name="bracket_to_ensenso_sof" type="fixed">
        <parent link="bracket" />
        <child link="ensenso_sensor_optical_frame" />
        <origin rpy="0 0 0" xyz="0 0.0909 0.1255" />
    </joint>
    <joint name="ensenso_move_frame_join" type="fixed">
        <parent link="ensenso_sensor_optical_frame" />
        <child link="kinect2_move_frame" />
        <origin rpy="0 -1.57079632679 0" />
    </joint>
    <link name="demo_cell_base_link" />
    <link name="demo_cell_corner" />
    <link name="demo_cell_back_wall">
        <collision>
            <geometry>
                <box size="0.05 3 5" />
            </geometry>
        </collision>
        
<inertial>
            <mass value="0.1" />
            <inertia ixx="0.03" iyy="0.03" izz="0.03" ixy="0.0" ixz="0.0" iyz="0.0" />
        </inertial>

    </link>
    <link name="demo_cell_right_wall">
        <collision>
            <geometry>
                <box size="4 0.05 5" />
            </geometry>
        </collision>
        
<inertial>
            <mass value="0.1" />
            <inertia ixx="0.03" iyy="0.03" izz="0.03" ixy="0.0" ixz="0.0" iyz="0.0" />
        </inertial>

    </link>
    <link name="demo_cell_left_wall">
        <collision>
            <geometry>
                <box size="4 0.05 5" />
            </geometry>
        </collision>
        
<inertial>
            <mass value="0.1" />
            <inertia ixx="0.03" iyy="0.03" izz="0.03" ixy="0.0" ixz="0.0" iyz="0.0" />
        </inertial>

    </link>
    <!-- light curtains -->
    <link name="demo_cell_front_wall">
        <collision>
            <geometry>
                <box size="0.05 3 5" />
            </geometry>
        </collision>
        
<inertial>
            <mass value="0.1" />
            <inertia ixx="0.03" iyy="0.03" izz="0.03" ixy="0.0" ixz="0.0" iyz="0.0" />
        </inertial>

    </link>
    <link name="demo_cell_roof">
        <collision>
            <geometry>
                <box size="4 3 0.05" />
            </geometry>
        </collision>
        
<inertial>
            <mass value="0.1" />
            <inertia ixx="0.03" iyy="0.03" izz="0.03" ixy="0.0" ixz="0.0" iyz="0.0" />
        </inertial>

    </link>
    <link name="demo_cell_floor">
        <collision>
            <geometry>
                <box size="4 3 0.05" />
            </geometry>
        </collision>
        
<inertial>
            <mass value="0.1" />
            <inertia ixx="0.03" iyy="0.03" izz="0.03" ixy="0.0" ixz="0.0" iyz="0.0" />
        </inertial>

    </link>
    <joint name="cell_baselink_to_corner" type="fixed">
        <parent link="demo_cell_base_link" />
        <child link="demo_cell_corner" />
        <origin xyz="-0.45 -0.762 0" />
    </joint>
    <joint name="cell_corner_to_back" type="fixed">
        <parent link="demo_cell_corner" />
        <child link="demo_cell_back_wall" />
        <origin xyz="-0.025 1.5 2.5" />
    </joint>
    <joint name="cell_corner_to_left" type="fixed">
        <parent link="demo_cell_corner" />
        <child link="demo_cell_left_wall" />
        <origin xyz="2.0 -0.025 2.5" />
    </joint>
    <joint name="cell_corner_to_front" type="fixed">
        <parent link="demo_cell_corner" />
        <child link="demo_cell_front_wall" />
        <origin xyz="4.025 1.5 2.5" />
    </joint>
    <joint name="cell_corner_to_right" type="fixed">
        <parent link="demo_cell_corner" />
        <child link="demo_cell_right_wall" />
        <origin xyz="2.0 3.025 2.5" />
    </joint>
    <joint name="cell_corner_to_roof" type="fixed">
        <parent link="demo_cell_corner" />
        <child link="demo_cell_roof" />
        <origin xyz="2.0 1.5 5.025" />
    </joint>
    <joint name="cell_corner_to_floor" type="fixed">
        <parent link="demo_cell_corner" />
        <child link="demo_cell_floor" />
        <origin xyz="2.0 1.5 -0.025" />
    </joint>
    <!-- Attach the end effector to the end of the robot arm (tool0) -->
    <joint name="link_t_to_eff" type="fixed">
        <parent link="tool0" />
        <child link="eff_frame" />
        <origin rpy="0 0 1.57079632679" xyz="0 0 0" />
    </joint>
    <!-- start of arm-workcell joint definitions -->
    <joint name="world_to_base" type="fixed">
        <parent link="world_frame" />
        <child link="base_link" />
        <origin rpy="0 0 0" xyz="0 0 0" />
    </joint>
    <joint name="world_to_demo_cell" type="fixed">
        <parent link="world_frame" />
        <child link="demo_cell_base_link" />
        <origin rpy="0 0 0" xyz="0 0 0" />
    </joint>
    
<transmission name="trans_joint_1">
        <type>transmission_interface/SimpleTransmission</type>
        <joint name="joint_1">
            <hardwareInterface>hardware_interface/EffortJointInterface</hardwareInterface>
        </joint>
        <actuator name="joint_1_motor">
            <hardwareInterface>hardware_interface/EffortJointInterface</hardwareInterface>
            <mechanicalReduction>1</mechanicalReduction>
        </actuator>
    </transmission>
    <transmission name="trans_joint_2">
        <type>transmission_interface/SimpleTransmission</type>
        <joint name="joint_2">
            <hardwareInterface>hardware_interface/EffortJointInterface</hardwareInterface>
        </joint>
        <actuator name="joint_2_motor">
            <hardwareInterface>hardware_interface/EffortJointInterface</hardwareInterface>
            <mechanicalReduction>1</mechanicalReduction>
        </actuator>
    </transmission>
    <transmission name="trans_joint_3">
        <type>transmission_interface/SimpleTransmission</type>
        <joint name="joint_3">
            <hardwareInterface>hardware_interface/EffortJointInterface</hardwareInterface>
        </joint>
        <actuator name="joint_3_motor">
            <hardwareInterface>hardware_interface/EffortJointInterface</hardwareInterface>
            <mechanicalReduction>1</mechanicalReduction>
        </actuator>
    </transmission>
    <transmission name="trans_joint_4">
        <type>transmission_interface/SimpleTransmission</type>
        <joint name="joint_4">
            <hardwareInterface>hardware_interface/EffortJointInterface</hardwareInterface>
        </joint>
        <actuator name="joint_4_motor">
            <hardwareInterface>hardware_interface/EffortJointInterface</hardwareInterface>
            <mechanicalReduction>1</mechanicalReduction>
        </actuator>
    </transmission>
    <transmission name="trans_joint_5">
        <type>transmission_interface/SimpleTransmission</type>
        <joint name="joint_5">
            <hardwareInterface>hardware_interface/EffortJointInterface</hardwareInterface>
        </joint>
        <actuator name="joint_5_motor">
            <hardwareInterface>hardware_interface/EffortJointInterface</hardwareInterface>
            <mechanicalReduction>1</mechanicalReduction>
        </actuator>
    </transmission>
    <transmission name="trans_joint_6">
        <type>transmission_interface/SimpleTransmission</type>
        <joint name="joint_6">
            <hardwareInterface>hardware_interface/EffortJointInterface</hardwareInterface>
        </joint>
        <actuator name="joint_6_motor">
            <hardwareInterface>hardware_interface/EffortJointInterface</hardwareInterface>
            <mechanicalReduction>1</mechanicalReduction>
        </actuator>
    </transmission>
    <gazebo>
        <plugin name="gazebo_ros_control" filename="libgazebo_ros_control.so">
            <robotNamespace>/</robotNamespace>
        </plugin>
    </gazebo>
</robot>